<?xml version="1.0"?>
<robot xmlns:xacro="http://www.ros.org/wiki/xacro">
    <xacro:macro name="reach_bravo7_quad_jaws" params="prefix">

        <link name="${prefix}/jaw_link">
            <visual>
                <geometry>
                    <mesh filename="package://blueprintlab_reachbravo7_manipulator_description/resources/meshes/end_effectors/quad_jaws/jaw.obj"/>
                </geometry>
            </visual>
            <inertial>
                <origin xyz="0 0 0" rpy="0 0 0"/>
                <mass value="1e-5"/>
                <inertia ixx="0.01" ixy="0.0" ixz="0.0" iyy="0.01" iyz="0.0" izz="0.01"/>
            </inertial>
        </link>

        <!-- Outside finger -->
        <link name="${prefix}/gripper_outside">
            <visual>
                <geometry>
                    <mesh filename="package://blueprintlab_reachbravo7_manipulator_description/resources/meshes/end_effectors/quad_jaws/gripper_outside.obj"/>
                </geometry>
                <origin rpy="0 0 0" xyz="0 0 0"/>
            </visual>
            <collision>
                <origin xyz="-0.0628 -0.0207 0.0" rpy="0 0 0.2584"/>
                <geometry>
                    <box size="0.149 0.0277 0.07"/>
                </geometry>
            </collision>
            <inertial>
                <origin xyz="0 0 0" rpy="0 0 0"/>
                <mass value="1e-5"/>
                <inertia ixx="0.01" ixy="0.0" ixz="0.0" iyy="0.01" iyz="0.0" izz="0.01"/>
            </inertial>
        </link>

        <!-- Inside finger -->
        <link name="${prefix}/gripper_inside">
            <visual>
                <geometry>
                    <mesh filename="package://blueprintlab_reachbravo7_manipulator_description/resources/meshes/end_effectors/quad_jaws/gripper_inside.obj"/>
                </geometry>
                <origin rpy="0 0 0" xyz="0 0 0"/>
            </visual>
            <collision>
                <origin xyz="-0.0628 0.0207 0.0" rpy="0 0 -0.2584"/>
                <geometry>
                    <box size="0.149 0.0277 0.05"/>
                </geometry>
            </collision>
            <inertial>
                <origin xyz="0 0 0" rpy="0 0 0"/>
                <mass value="1e-5"/>
                <inertia ixx="0.01" ixy="0.0" ixz="0.0" iyy="0.01" iyz="0.0" izz="0.01"/>
            </inertial>
        </link>

        <joint name="${prefix}/jaw_joint" type="fixed">
            <origin rpy="0 0 ${pi/2}" xyz="0.0 0.0 ${0.124 + 0.0097}"/>
            <parent link="${prefix}/link6"/>
            <child link="${prefix}/jaw_link"/>
        </joint>

        <joint name="${prefix}/gripper_outside_joint" type="revolute">
            <origin rpy="0 ${pi/2} 0" xyz="0 0.033 0"/>
            <parent link="${prefix}/jaw_link"/>
            <child link="${prefix}/gripper_outside"/>
            <axis xyz="0 0 1"/>
            <limit effort="10" lower="0" upper="0.5" velocity="10"/>
            <mimic joint="${prefix}/push_rod" multiplier="-0.1" offset="0"/>
        </joint>


        <joint name="${prefix}/gripper_inside_joint" type="revolute">
            <origin rpy="0 ${pi/2} 0" xyz="0 -0.033 0"/>
            <parent link="${prefix}/jaw_link"/>
            <child link="${prefix}/gripper_inside"/>
            <axis xyz="0 0 1"/>
            <limit effort="10" lower="0" upper="0.5" velocity="10"/>
            <mimic joint="${prefix}/push_rod" multiplier="0.1" offset="0"/>
        </joint>

    </xacro:macro>
</robot>